<?xml version='1.0'?>
<sdf version='1.5'>
  <model name="orthrus">
    <pose>0 0 0.12 0 0 0</pose>

    <link name="body">
      <pose>0 0 0 0 0 0</pose>
      
      <inertial>
        <mass>10.0</mass>
        <inertia> 
          <ixx>0.036788030</ixx>
          <ixy>0</ixy>
          <ixz>0</ixz>
          <iyy>0.056803600</iyy> 
          <iyz>0</iyz>
          <izz>0.077591097</izz>
        </inertia>
      </inertial>

      <collision name="collision">
        <geometry>
          <mesh>
            <uri>model://orthrus/meshes/body.dae</uri>
          </mesh>
        </geometry>

        <surface>
          <friction>
            <ode>
              <mu>1</mu>
              <mu2>1</mu2>
              <slip1>0.5</slip1>
              <slip2>0</slip2>
            </ode>
          </friction>
        </surface>
      </collision>
      

      <visual name='visual'>
        <geometry>
          <mesh>
            <uri>model://orthrus/meshes/body.dae</uri>
          </mesh>
        </geometry>
      </visual>

    </link>
    
    <link name="hip_RF">
      <pose>0.175 -0.05 0 0 0 0</pose>
      <inertial>
        <mass>0.8</mass>
        <inertia> 
          <ixx>0.000872681</ixx>
          <ixy>0</ixy>
          <ixz>0.000001665</ixz>
          <iyy>0.000609006</iyy> 
          <iyz>-0.000000001</iyz>
          <izz>0.000545546</izz>
        </inertia>
      </inertial>

      <collision name="collision">
        <geometry>
          <mesh>
            <uri>model://orthrus/meshes/hip_RF.dae</uri>
          </mesh>
        </geometry>

        <surface>
          <friction>
            <ode>
              <mu>1</mu>
              <mu2>1</mu2>
              <slip1>0.5</slip1>
              <slip2>0</slip2>
            </ode>
          </friction>
        </surface>
      </collision>
      

      <visual name='visual'>
        <geometry>
          <mesh>
            <uri>model://orthrus/meshes/hip_RF.dae</uri>
          </mesh>
        </geometry>
      </visual>    
    </link>
    

    <link name="hip_LF">
      <pose>0.175 0.05 0 0 0 0</pose>
      <inertial>
        <mass>0.8</mass>
        <inertia> 
          <ixx>0.000872681</ixx>
          <ixy>0</ixy>
          <ixz>0.000001665</ixz>
          <iyy>0.000609006</iyy> 
          <iyz>-0.000000001</iyz>
          <izz>0.000545546</izz>
        </inertia>
      </inertial>

      <collision name="collision">
        <geometry>
          <mesh>
            <uri>model://orthrus/meshes/hip_LF.dae</uri>
          </mesh>
        </geometry>

        <surface>
          <friction>
            <ode>
              <mu>1</mu>
              <mu2>1</mu2>
              <slip1>0.5</slip1>
              <slip2>0</slip2>
            </ode>
          </friction>
        </surface>
      </collision>
      
      <visual name='visual'>
        <geometry>
          <mesh>
            <uri>model://orthrus/meshes/hip_LF.dae</uri>
          </mesh>
        </geometry>
      </visual>    
    </link>
    
    <link name="hip_RB">
      <pose>-0.175 -0.05 0 0 0 0</pose>
      <inertial>
        <mass>0.8</mass>
        <inertia> 
          <ixx>0.000872681</ixx>
          <ixy>0</ixy>
          <ixz>0.000001665</ixz>
          <iyy>0.000609006</iyy> 
          <iyz>-0.000000001</iyz>
          <izz>0.000545546</izz>
        </inertia>
      </inertial>

      <collision name="collision">

        <geometry>
          <mesh>
            <uri>model://orthrus/meshes/hip_RB.dae</uri>
          </mesh>
        </geometry>

        <surface>
          <friction>
            <ode>
              <mu>1</mu>
              <mu2>1</mu2>
              <slip1>0.5</slip1>
              <slip2>0</slip2>
            </ode>
          </friction>
        </surface>

      </collision>
      

      <visual name='visual'>
        <geometry>
          <mesh>
            <uri>model://orthrus/meshes/hip_RB.dae</uri>
          </mesh>
        </geometry>
      </visual>    
    </link>
    
    <link name="hip_LB">
      <pose>-0.175 0.05 0 0 0 0</pose>
      <inertial>
        <mass>0.8</mass>
        <inertia> 
          <ixx>0.000872681</ixx>
          <ixy>0</ixy>
          <ixz>0.000001665</ixz>
          <iyy>0.000609006</iyy> 
          <iyz>-0.000000001</iyz>
          <izz>0.000545546</izz>
        </inertia>
      </inertial>

      <collision name="collision">

        <geometry>
          <mesh>
            <uri>model://orthrus/meshes/hip_LB.dae</uri>
          </mesh>
        </geometry>

        <surface>
          <friction>
            <ode>
              <mu>1</mu>
              <mu2>1</mu2>
              <slip1>0.5</slip1>
              <slip2>0</slip2>
            </ode>
          </friction>
        </surface>
      </collision>
      
      <visual name='visual'>
        <geometry>
          <mesh>
            <uri>model://orthrus/meshes/hip_LB.dae</uri>
          </mesh>
        </geometry>
      </visual>    
    </link>

    
    <link name="RF_leg_1">
      <pose>0.175 -0.069 0 0 0 0</pose>
      <inertial>
        <mass>1.3</mass>
        <inertia> 
          <ixx>0.005030229</ixx>
          <ixy>-0.000281110</ixy>
          <ixz>0.000001665</ixz>
          <iyy>0.001229771</iyy>
          <iyz>-0.000689921</iyz>
          <izz>0.004833226</izz>
        </inertia>
      </inertial>

      <collision name="collision">

        <geometry>
          <mesh>
            <uri>model://orthrus/meshes/leg_R_1.dae</uri>
          </mesh>
        </geometry>

        <surface>
          <friction>
            <ode>
              <mu>1</mu>
              <mu2>1</mu2>
              <slip1>0.5</slip1>
              <slip2>0</slip2>
            </ode>
          </friction>
        </surface>

      </collision>
      

      <visual name='visual'>
        <geometry>
          <mesh>
            <uri>model://orthrus/meshes/leg_R_1.dae</uri>
          </mesh>
        </geometry>
      </visual>    
    </link>

    <!--LEG_1-->

    <link name="LF_leg_1">
      <pose>0.175 0.069 0 0 0 0</pose>
      <inertial>
        <mass>1.3</mass>
        <inertia> 
          <ixx>0.005030229</ixx>
          <ixy>-0.000281110</ixy>
          <ixz>0.000001665</ixz>
          <iyy>0.001229771</iyy>
          <iyz>-0.000689921</iyz>
          <izz>0.004833226</izz>
        </inertia>
      </inertial>

      <collision name="collision">

        <geometry>
          <mesh>
            <uri>model://orthrus/meshes/leg_L_1.dae</uri>
          </mesh>
        </geometry>

        <surface>
          <friction>
            <ode>
              <mu>1</mu>
              <mu2>1</mu2>
              <slip1>0.5</slip1>
              <slip2>0</slip2>
            </ode>
          </friction>
        </surface>

      </collision>
      

      <visual name='visual'>
        <geometry>
          <mesh>
            <uri>model://orthrus/meshes/leg_L_1.dae</uri>
          </mesh>
        </geometry>
      </visual>    
    </link>

    <link name="RB_leg_1">
      <pose>-0.175 -0.069 0 0 0 0</pose>
      <inertial>
        <mass>1.3</mass>
        <inertia> 
          <ixx>0.005030229</ixx>
          <ixy>-0.000281110</ixy>
          <ixz>0.000001665</ixz>
          <iyy>0.001229771</iyy>
          <iyz>-0.000689921</iyz>
          <izz>0.004833226</izz>
        </inertia>
      </inertial>

      <collision name="collision">

        <geometry>
          <mesh>
            <uri>model://orthrus/meshes/leg_R_1.dae</uri>
          </mesh>
        </geometry>

        <surface>
          <friction>
            <ode>
              <mu>1</mu>
              <mu2>1</mu2>
              <slip1>0.5</slip1>
              <slip2>0</slip2>
            </ode>
          </friction>
        </surface>

      </collision>
      

      <visual name='visual'>
        <geometry>
          <mesh>
            <uri>model://orthrus/meshes/leg_R_1.dae</uri>
          </mesh>
        </geometry>
      </visual>    
    </link>

    <link name="LB_leg_1">
      <pose>-0.175 0.069 0 0 0 0</pose>
      <inertial>
        <mass>1.3</mass>
        <inertia> 
          <ixx>0.005030229</ixx>
          <ixy>-0.000281110</ixy>
          <ixz>0.000001665</ixz>
          <iyy>0.001229771</iyy>
          <iyz>-0.000689921</iyz>
          <izz>0.004833226</izz>
        </inertia>
      </inertial>

      <collision name="collision">

        <geometry>
          <mesh>
            <uri>model://orthrus/meshes/leg_L_1.dae</uri>
          </mesh>
        </geometry>

        <surface>
          <friction>
            <ode>
              <mu>1</mu>
              <mu2>1</mu2>
              <slip1>0.5</slip1>
              <slip2>0</slip2>
            </ode>
          </friction>
        </surface>

      </collision>
      

      <visual name='visual'>
        <geometry>
          <mesh>
            <uri>model://orthrus/meshes/leg_L_1.dae</uri>
          </mesh>
        </geometry>
      </visual>    
    </link>

    <!--LEG_2-->

    <link name="RF_leg_2">
      <pose>-0.005 -0.133 0 0 0.52359876 0</pose>
      <inertial>
        <mass>0.4</mass>
        <inertia> 
          <ixx>0.000039684</ixx>
          <ixy>-0.000000001</ixy>
          <ixz>0.000174506</ixz>
          <iyy>0.005380513</iyy>
          <iyz>-0.000000003</iyz>
          <izz>0.005364733</izz>
        </inertia>
      </inertial>

      <collision name="collision">

        <geometry>
          <mesh>
            <uri>model://orthrus/meshes/leg_2.dae</uri>
          </mesh>
        </geometry>

        <surface>
          <friction>
            <ode>
              <mu>1</mu>
              <mu2>1</mu2>
              <slip1>0.5</slip1>
              <slip2>0</slip2>
            </ode>
          </friction>
        </surface>
      </collision>
      
      <visual name='visual'>
        <geometry>
          <mesh>
            <uri>model://orthrus/meshes/leg_2.dae</uri>
          </mesh>
        </geometry>
      </visual>    
    </link>

    <link name="LF_leg_2">
      <pose>-0.005 0.133 0 0 0.52359876 0</pose>
      <inertial>
        <mass>0.4</mass>
        <inertia> 
          <ixx>0.000039684</ixx>
          <ixy>-0.000000001</ixy>
          <ixz>0.000174506</ixz>
          <iyy>0.005380513</iyy>
          <iyz>-0.000000003</iyz>
          <izz>0.005364733</izz>
        </inertia>
      </inertial>

      <collision name="collision">

        <geometry>
          <mesh>
            <uri>model://orthrus/meshes/leg_2.dae</uri>
          </mesh>
        </geometry>

        <surface>
          <friction>
            <ode>
              <mu>1</mu>
              <mu2>1</mu2>
              <slip1>0.5</slip1>
              <slip2>0</slip2>
            </ode>
          </friction>
        </surface>

      </collision>
      

      <visual name='visual'>
        <geometry>
          <mesh>
            <uri>model://orthrus/meshes/leg_2.dae</uri>
          </mesh>
        </geometry>
      </visual>    
    </link>
    
    <link name="RB_leg_2">
      <pose>-0.355 -0.133 0 0 0.52359876 0</pose>
      <inertial>
        <mass>0.4</mass>
        <inertia> 
          <ixx>0.000039684</ixx>
          <ixy>-0.000000001</ixy>
          <ixz>0.000174506</ixz>
          <iyy>0.005380513</iyy>
          <iyz>-0.000000003</iyz>
          <izz>0.005364733</izz>
        </inertia>
      </inertial>

      <collision name="collision">

        <geometry>
          <mesh>
            <uri>model://orthrus/meshes/leg_2.dae</uri>
          </mesh>
        </geometry>

        <surface>
          <friction>
            <ode>
              <mu>1</mu>
              <mu2>1</mu2>
              <slip1>0.5</slip1>
              <slip2>0</slip2>
            </ode>
          </friction>
        </surface>

      </collision>
      

      <visual name='visual'>
        <geometry>
          <mesh>
            <uri>model://orthrus/meshes/leg_2.dae</uri>
          </mesh>
        </geometry>
      </visual>    
    </link>

    <link name="LB_leg_2">
      <pose>-0.355 0.133 0 0 0.52359876 0</pose>
      <inertial>
        <mass>0.4</mass>
        <inertia> 
          <ixx>0.000039684</ixx>
          <ixy>-0.000000001</ixy>
          <ixz>0.000174506</ixz>
          <iyy>0.005380513</iyy>
          <iyz>-0.000000003</iyz>
          <izz>0.005364733</izz>
        </inertia>
      </inertial>

      <collision name="collision">

        <geometry>
          <mesh>
            <uri>model://orthrus/meshes/leg_2.dae</uri>
          </mesh>
        </geometry>

        <surface>
          <friction>
            <ode>
              <mu>1</mu>
              <mu2>1</mu2>
              <slip1>0.5</slip1>
              <slip2>0</slip2>
            </ode>
          </friction>
        </surface>

      </collision>
      

      <visual name='visual'>
        <geometry>
          <mesh>
            <uri>model://orthrus/meshes/leg_2.dae</uri>
          </mesh>
        </geometry>
      </visual>    
    </link>


      
      


    
    <joint name='RF_joint_1' type='revolute'>
      <parent>body</parent>
      <child>hip_RF</child>
      <axis>
        <xyz>1 0 0</xyz>
        <limit>
          <lower> -1.5714</lower>
          <upper> 1.5714</upper>
        </limit>
        <dynamics>
          <damping>1.000000</damping>
          <friction>0.000000</friction>
        </dynamics>
        <use_parent_model_frame>true</use_parent_model_frame>
      </axis>
      <physics>
        <provide_feedback> true </provide_feedback>
        <ode>
          <erp> 0.5 </erp>
        </ode>
      </physics>
    </joint>
     
    <joint name='LF_joint_1' type='revolute'>
      <parent>body</parent>
      <child>hip_LF</child>
      <axis>
        <xyz>1 0 0</xyz>
        <limit>
          <lower> -1.5714</lower>
          <upper> 1.5714</upper>
        </limit>
        <dynamics>
          <damping>1.000000</damping>
          <friction>0.000000</friction>
        </dynamics>
        <use_parent_model_frame>true</use_parent_model_frame>
      </axis>
    </joint>
    
    <joint name='RB_joint_1' type='revolute'>
      <parent>body</parent>
      <child>hip_RB</child>
      <axis>
        <xyz>1 0 0</xyz>
        <limit>
          <lower> -1.5714</lower>
          <upper> 1.5714</upper>
        </limit>
        <dynamics>
          <damping>1.000000</damping>
          <friction>0.000000</friction>
        </dynamics>
        <use_parent_model_frame>true</use_parent_model_frame>
      </axis>
    </joint>
    
    <joint name='LB_joint_1' type='revolute'>
      <parent>body</parent>
      <child>hip_LB</child>
      <axis>
        <xyz>1 0 0</xyz>
        <limit>
          <lower> -1.5714</lower>
          <upper> 1.5714</upper>
        </limit>
        <dynamics>
          <damping>1.000000</damping>
          <friction>0.000000</friction>
        </dynamics>
        <use_parent_model_frame>true</use_parent_model_frame>
      </axis>
    </joint>

    <joint name='RF_joint_2' type='revolute'>
      <parent>hip_RF</parent>
      <child>RF_leg_1</child>
      <axis>
        <xyz>0 1 0</xyz>
        <dynamics>
          <damping>1.000000</damping>
          <friction>0.000000</friction>
        </dynamics>
        <use_parent_model_frame>true</use_parent_model_frame>
      </axis>
    </joint>

    <joint name='LF_joint_2' type='revolute'>
      <parent>hip_LF</parent>
      <child>LF_leg_1</child>
      <axis>
        <xyz>0 1 0</xyz>
        <dynamics>
          <damping>1.000000</damping>
          <friction>0.000000</friction>
        </dynamics>
        <use_parent_model_frame>true</use_parent_model_frame>
      </axis>
    </joint>
    
    <joint name='RB_joint_2' type='revolute'>
      <parent>hip_RB</parent>
      <child>RB_leg_1</child>
      <axis>
        <xyz>0 1 0</xyz>
        <dynamics>
          <damping>1.000000</damping>
          <friction>0.000000</friction>
        </dynamics>
        <use_parent_model_frame>true</use_parent_model_frame>
      </axis>
    </joint>
    
    <joint name='LB_joint_2' type='revolute'>
      <parent>hip_LB</parent>
      <child>LB_leg_1</child>
      <axis>
        <xyz>0 1 0</xyz>
        <dynamics>
          <damping>1.000000</damping>
          <friction>0.000000</friction>
        </dynamics>
        <use_parent_model_frame>true</use_parent_model_frame>
      </axis>
    </joint>

    <joint name='RF_joint_3' type='revolute'>
      <parent>RF_leg_1</parent>
      <child>RF_leg_2</child>

      <axis>
        <xyz>0 1 0</xyz>
        <limit>
          <lower> -0.18 </lower>
          <upper> 1.5714</upper>
        </limit>
        <dynamics>
          <damping>1.000000</damping>
          <friction>0.000000</friction>
        </dynamics>
        <use_parent_model_frame>true</use_parent_model_frame>
      </axis>
    </joint>
     
    <joint name='LF_joint_3' type='revolute'>
      <parent>LF_leg_1</parent>
      <child>LF_leg_2</child>
      <axis>
        <xyz>0 1 0</xyz>
        <limit>
          <lower> -0.18 </lower>
          <upper> 1.5714</upper>
        </limit>
        <dynamics>
          <damping>1.000000</damping>
          <friction>0.000000</friction>
        </dynamics>
        <use_parent_model_frame>true</use_parent_model_frame>
      </axis>
    </joint>

    <joint name='RB_joint_3' type='revolute'>
      <parent>RB_leg_1</parent>
      <child>RB_leg_2</child>
      <axis>
        <xyz>0 1 0</xyz>
        <limit>
          <lower> -0.18 </lower>
          <upper> 1.5714</upper>
        </limit>
        <dynamics>
          <damping>1.000000</damping>
          <friction>0.000000</friction>
        </dynamics>
        <use_parent_model_frame>true</use_parent_model_frame>
      </axis>
    </joint>

        <joint name='LB_joint_3' type='revolute'>
      <parent>LB_leg_1</parent>
      <child>LB_leg_2</child>
      <axis>
        <xyz>0 1 0</xyz>
        <limit>
          <lower> -0.18 </lower>
          <upper> 1.5714</upper>
        </limit>
        <dynamics>
          <damping>1.000000</damping>
          <friction>0.000000</friction>
        </dynamics>
        <use_parent_model_frame>true</use_parent_model_frame>
      </axis>
    </joint>

    
    
  </model>
</sdf>
